Workbook
Name A: #REF!
Name aaa: #REF!
Name b: #REF!
Name costoacquasanitaria: #REF!
Name costoafs: #REF!
Name costoenegiaelettrica: #REF!
Name D: #REF!
Name DINO: #REF!
Name Nom_Nouveau: #REF!
Name Nom_Quad: #REF!
Name rate: #REF!
Name Righe_Rimaste: #REF!
Name Verifica: #REF!
Name costoenegiaelettrica: 'Ripartizione_Termo 02.03.2026'!$C$26
Name costoafs: Tabella_2026!$E$13
Name costoenegiaelettrica: #REF!
Name costoafs: #REF!
Name costoenegiaelettrica: #REF!

Sheet Ripartizione_Termo 02.03.2026
A1: Condomini | C1: Millesimi riscaldamento | D1: Millesimi acqua calda sanitaria
C2: Mill. | D2: Mill.
A3: App. 01 | C3: ='Tabelle millesimali'!D4 | D3: ='Tabelle millesimali'!F4
A4: App. 02 | C4: ='Tabelle millesimali'!D5 | D4: ='Tabelle millesimali'!F5
A5: App. 03 | C5: ='Tabelle millesimali'!D6 | D5: ='Tabelle millesimali'!F6
A6: App. 04 | C6: ='Tabelle millesimali'!D7 | D6: ='Tabelle millesimali'!F7
A7: App. 05 | C7: ='Tabelle millesimali'!D8 | D7: ='Tabelle millesimali'!F8
A8: App. 06 | C8: ='Tabelle millesimali'!D9 | D8: ='Tabelle millesimali'!F9
A9: App. 07 | C9: ='Tabelle millesimali'!D10 | D9: ='Tabelle millesimali'!F10
A10: App. 08 | C10: ='Tabelle millesimali'!D11 | D10: ='Tabelle millesimali'!F11
A11: App. 09 | C11: ='Tabelle millesimali'!D12 | D11: ='Tabelle millesimali'!F12
A12: App. 10 | C12: ='Tabelle millesimali'!D13 | D12: ='Tabelle millesimali'!F13
A14: TOTALE | C14: =SUM(C3:C12) | D14: =SUM(D3:D12)
A17: CALCOLO DELLA RIPARTIZIONE
A18: I valori sono quelli reali. Aggiornando i dati nelle celle gialle e rosa con i valori dell'anno corrente si ottiene la ripartizione
A19: Impianto: rsicaldamento a colonne montanti + acqua calda sanitaria centralizzata
A21: Costo complessivo GAS METANO | B21: € | C21: =Tabella_2026!E4 | D21: da tabella
A22: Gas Metano lettura INIZIALE | B22: mc | C22: =Tabella_2026!F21
A23: Gas Metano lettura FINALE | B23: mc | C23: =Tabella_2026!H21 | D23: da tabella
A24: costo medio metano | B24: €/mc | C24: =C21/(C23-C22)
A25: Consumo energia elettrica per CT | B25: kWh | C25: =SUM(Tabella_2026!G20) | D25: da tabella
A26: Costo medio enegia elettrica | B26: €/kwh | C26: =Tabella_2026!E12
A27: Lettura contabilizzatore x RISCALDAMENTO INIZIO ESERCIZIO | B27: kWh | C27: 21778 | D27: 46022 | E27: da prec. Es
A28: Lettura contabilizzatore x RISCALDAMENTO FINE GESTIONE 25 | B28: kWh | E28: da letture Siemems
A29: consumo energetico per RISCALDAMENTO | B29: kWh | C29: =(C28-C27) | D29: = CONSUMO
A30: Lettura contabilizzatore x ACS in ct INIZIO ESERCIZIO | B30: kWh | C30: 26256 | D30: 46022 | E30: da prec. Es
A31: Lettura contabilizzatore x ACS in ct FINE GESTIONE 25 | B31: kWh | E31: da letture Siemems
A32: consumo energetico per riscaldamento ACS | B32: kWh | C32: =(C31-C30) | D32: = CONSUMO
A35: Calcolo del costo dell'energia utile prodotta
A36: Consumo metano | B36: m³ | C36: =C23-C22
A37: Costo TOTALE metano | B37: € | C37: =C21
B38: €/m³ | C38: =+C37/C36
A40: Potere calorifico metano | B40: kWh/m³ | C40: 9.45
A41: Consumo metano | B41: kWh | C41: =+C36*C40
A43: Consumo energia elettrica | B43: kWh | C43: =C25
A44: Costo energia elettrica | B44: €/kWh | C44: =costoenegiaelettrica
B45: € | C45: =+C43*C44
A47: Costo totale | B47: € | C47: =+C45+C37
A48: Rendimento generatore | B48: % | C48: 93
A49: Energia utile prodotta dal generatore | B49: kWh | C49: =+C41*C48/100
...

Sheet Tabella_2026
B2: verifiche | F2: Data
B3: Spesa enegia elettrica da dividere x termico
B4: Spesa GAS da dividere condominio | G4: =SUM(E3:E4)
B5: Spesa ACQUA del condominio
B6: Spese di conduzione e manutenzione
B7: Spese di contabilizzazione
B8: Spese ad acqua SANITARIA (Sali + manutenzione)
E9: =SUM(E3:E8)
B12: Costo medio energia elettrica €/kWh | E12: =E3/H20
B13: Costo medio AFS €/mc | E13: =E5/('Ripartizione_Termo 02.03.2026'!D200+'Ripartizione_Termo 02.03.2026'!E200)
B14: Costo medio gas metano €/mc | E14: =E4/H21
B17: LETTURA CONTATORI PRINCIPALI | E17: DATA
G18: ??/??/???? | H18: CONSUMO
G19: da fatture
B20: ENERGIA ELETTRICA CT | E20: Kwh | H20: =G20-F20
B21: GAS METANO CT | E21: mc | H21: =G21-F21
B22: ACQUA GENERALE ACQUEDOTTO | E22: mc | H22: =G22-F22

Sheet Tabelle millesimali
A1: Condomini | C1: Energia utile riscaldamento | D1: Millesimi riscaldamento | E1: Energia utile acqua calda sanitaria | F1: Millesimi acqua calda sanitaria
C2: kWh | D2: Mill. | E2: kWh | F2: Mill.
A3: TOTALE | B3: SUBALTERNO | C3: =SUM(C4:C15) | D3: =SUM(D4:D15) | E3: =SUM(E4:E15) | F3: =SUM(F4:F15)
D4: =C4/$C$3*1000 | F4: =+E4/$E$3*1000
D5: =C5/$C$3*1000 | F5: =+E5/$E$3*1000
D6: =C6/$C$3*1000 | F6: =+E6/$E$3*1000
D7: =C7/$C$3*1000 | F7: =+E7/$E$3*1000
D8: =C8/$C$3*1000 | F8: =+E8/$E$3*1000
D9: =C9/$C$3*1000 | F9: =+E9/$E$3*1000
D10: =C10/$C$3*1000 | F10: =+E10/$E$3*1000
D11: =C11/$C$3*1000 | F11: =+E11/$E$3*1000
D12: =C12/$C$3*1000 | F12: =+E12/$E$3*1000
D13: =C13/$C$3*1000 | F13: =+E13/$E$3*1000
D14: =C14/$C$3*1000 | F14: =+E14/$E$3*1000
D15: =C15/$C$3*1000 | F15: =+E15/$E$3*1000
C17: kcli | E17: kacs
C18: =+C3/(C3+E3) | E18: =+E3/(C3+E3)
